<?xml version="1.0" ?>
<!-- =================================================================================== -->
<!-- |    This document was autogenerated by xacro from /home/navneeth/catkin_ws/src/moveo-0105/moveo-0105_description/urdf/moveo-0105.xacro | -->
<!-- |    EDITING THIS FILE BY HAND IS NOT RECOMMENDED                                 | -->
<!-- =================================================================================== -->
<robot name="moveo-0105">
    <material name="silver_default">
        <color rgba="0.700 0.700 0.700 1.000" />
    </material>
    <material name="opaque246246243">
        <color rgba="0.9647058823529412 0.9647058823529412 0.9529411764705882 1.0" />
    </material>
    <material name="abs_white">
        <color rgba="0.9647058823529412 0.9647058823529412 0.9529411764705882 1.0" />
    </material>
    <transmission name="Revolute 1_tran">
        <type>transmission_interface/SimpleTransmission</type>
        <joint name="Revolute 1">
            <hardwareInterface>hardware_interface/EffortJointInterface</hardwareInterface>
        </joint>
        <actuator name="Revolute 1_actr">
            <hardwareInterface>hardware_interface/EffortJointInterface</hardwareInterface>
            <mechanicalReduction>1</mechanicalReduction>
        </actuator>
    </transmission>
    <transmission name="Revolute 2_tran">
        <type>transmission_interface/SimpleTransmission</type>
        <joint name="Revolute 2">
            <hardwareInterface>hardware_interface/EffortJointInterface</hardwareInterface>
        </joint>
        <actuator name="Revolute 2_actr">
            <hardwareInterface>hardware_interface/EffortJointInterface</hardwareInterface>
            <mechanicalReduction>1</mechanicalReduction>
        </actuator>
    </transmission>
    <transmission name="Revolute 4_tran">
        <type>transmission_interface/SimpleTransmission</type>
        <joint name="Revolute 4">
            <hardwareInterface>hardware_interface/EffortJointInterface</hardwareInterface>
        </joint>
        <actuator name="Revolute 4_actr">
            <hardwareInterface>hardware_interface/EffortJointInterface</hardwareInterface>
            <mechanicalReduction>1</mechanicalReduction>
        </actuator>
    </transmission>
    <transmission name="Revolute 5_tran">
        <type>transmission_interface/SimpleTransmission</type>
        <joint name="Revolute 5">
            <hardwareInterface>hardware_interface/EffortJointInterface</hardwareInterface>
        </joint>
        <actuator name="Revolute 5_actr">
            <hardwareInterface>hardware_interface/EffortJointInterface</hardwareInterface>
            <mechanicalReduction>1</mechanicalReduction>
        </actuator>
    </transmission>
    <transmission name="Revolute 6_tran">
        <type>transmission_interface/SimpleTransmission</type>
        <joint name="Revolute 6">
            <hardwareInterface>hardware_interface/EffortJointInterface</hardwareInterface>
        </joint>
        <actuator name="Revolute 6_actr">
            <hardwareInterface>hardware_interface/EffortJointInterface</hardwareInterface>
            <mechanicalReduction>1</mechanicalReduction>
        </actuator>
    </transmission>
    <gazebo>
        <plugin filename="libgazebo_ros_control.so" name="control" />
        <plugin name="gazebo_ros_control">
            <robotNamespace>/</robotNamespace>
        </plugin>
    </gazebo>
    <gazebo reference="base_link">
        <material>Gazebo/Silver</material>
        <mu1>0.2</mu1>
        <mu2>0.2</mu2>
        <selfCollide>true</selfCollide>
        <gravity>true</gravity>
    </gazebo>
    <gazebo reference="base_1">
        <material>Gazebo/Silver</material>
        <mu1>0.2</mu1>
        <mu2>0.2</mu2>
        <selfCollide>true</selfCollide>
    </gazebo>
    <gazebo reference="shoulder_1">
        <material>Gazebo/Silver</material>
        <mu1>0.2</mu1>
        <mu2>0.2</mu2>
        <selfCollide>true</selfCollide>
    </gazebo>
    <gazebo reference="elbow_1">
        <material>Gazebo/Silver</material>
        <mu1>0.2</mu1>
        <mu2>0.2</mu2>
        <selfCollide>true</selfCollide>
    </gazebo>
    <gazebo reference="wrist1_1">
        <material>Gazebo/Silver</material>
        <mu1>0.2</mu1>
        <mu2>0.2</mu2>
        <selfCollide>true</selfCollide>
    </gazebo>
    <gazebo reference="wrist2_1">
        <material>Gazebo/Silver</material>
        <mu1>0.2</mu1>
        <mu2>0.2</mu2>
        <selfCollide>true</selfCollide>
    </gazebo>
    <gazebo reference="gripper_base_1">
        <material>Gazebo/Silver</material>
        <mu1>0.2</mu1>
        <mu2>0.2</mu2>
        <selfCollide>true</selfCollide>
    </gazebo>
    <link name="base_link">
        <inertial>
            <origin rpy="0 0 0" xyz="-0.04353915195820223 1.1802868267869896e-05 0.02880043175983316" />
            <mass value="14.165231902745852" />
            <inertia ixx="0.043748" ixy="1.1e-05" ixz="-0.004239" iyy="0.104813" iyz="3e-06" izz="0.129844" />
        </inertial>
        <visual>
            <origin rpy="0 0 0" xyz="0 0 0" />
            <geometry>
                <mesh filename="package://moveo-0105_description/meshes/base_link.stl" scale="0.001 0.001 0.001" />
            </geometry>
            <material name="opaque246246243" />
        </visual>
        <collision>
            <origin rpy="0 0 0" xyz="0 0 0" />
            <geometry>
                <mesh filename="package://moveo-0105_description/meshes/base_link.stl" scale="0.001 0.001 0.001" />
            </geometry>
        </collision>
    </link>
    <link name="base_1">
        <inertial>
            <origin rpy="0 0 0" xyz="-3.7076303009149166e-05 0.014076271479158351 0.07047518337511922" />
            <mass value="13.837333116090063" />
            <inertia ixx="0.087139" ixy="2.4e-05" ixz="-1.5e-05" iyy="0.056559" iyz="0.005688" izz="0.05967" />
        </inertial>
        <visual>
            <origin rpy="0 0 0" xyz="-0.0 -0.0 -0.081" />
            <geometry>
                <mesh filename="package://moveo-0105_description/meshes/base_1.stl" scale="0.001 0.001 0.001" />
            </geometry>
            <material name="opaque246246243" />
        </visual>
        <collision>
            <origin rpy="0 0 0" xyz="-0.0 -0.0 -0.081" />
            <geometry>
                <mesh filename="package://moveo-0105_description/meshes/base_1.stl" scale="0.001 0.001 0.001" />
            </geometry>
        </collision>
    </link>
    <link name="shoulder_1">
        <inertial>
            <origin rpy="0 0 0" xyz="-1.864413666055061e-05 -0.0016829757344041373 0.079876392750896" />
            <mass value="15.137044414850111" />
            <inertia ixx="0.134132" ixy="2.6e-05" ixz="0.000117" iyy="0.127723" iyz="0.000957" izz="0.028256" />
        </inertial>
        <visual>
            <origin rpy="0 0 0" xyz="-0.0 -0.0 -0.223" />
            <geometry>
                <mesh filename="package://moveo-0105_description/meshes/shoulder_1.stl" scale="0.001 0.001 0.001" />
            </geometry>
            <material name="opaque246246243" />
        </visual>
        <collision>
            <origin rpy="0 0 0" xyz="-0.0 -0.0 -0.223" />
            <geometry>
                <mesh filename="package://moveo-0105_description/meshes/shoulder_1.stl" scale="0.001 0.001 0.001" />
            </geometry>
        </collision>
    </link>
    <link name="elbow_1">
        <inertial>
            <origin rpy="0 0 0" xyz="1.0586701587362072e-07 2.396546815964754e-07 0.04247458254047237" />
            <mass value="0.7464260010795348" />
            <inertia ixx="0.002345" ixy="0.0" ixz="0.0" iyy="0.002358" iyz="0.0" izz="0.000749" />
        </inertial>
        <visual>
            <origin rpy="0 0 0" xyz="0.0 0.0 -0.444124" />
            <geometry>
                <mesh filename="package://moveo-0105_description/meshes/elbow_1.stl" scale="0.001 0.001 0.001" />
            </geometry>
            <material name="abs_white" />
        </visual>
        <collision>
            <origin rpy="0 0 0" xyz="0.0 0.0 -0.444124" />
            <geometry>
                <mesh filename="package://moveo-0105_description/meshes/elbow_1.stl" scale="0.001 0.001 0.001" />
            </geometry>
        </collision>
    </link>
    <link name="wrist1_1">
        <inertial>
            <origin rpy="0 0 0" xyz="0.00015462808202342042 0.0025523371121374885 0.055229105478112106" />
            <mass value="2.633340777705091" />
            <inertia ixx="0.005484" ixy="-8e-06" ixz="3.8e-05" iyy="0.004502" iyz="8.8e-05" izz="0.002738" />
        </inertial>
        <visual>
            <origin rpy="0 0 0" xyz="0.0 1e-06 -0.577624" />
            <geometry>
                <mesh filename="package://moveo-0105_description/meshes/wrist1_1.stl" scale="0.001 0.001 0.001" />
            </geometry>
            <material name="opaque246246243" />
        </visual>
        <collision>
            <origin rpy="0 0 0" xyz="0.0 1e-06 -0.577624" />
            <geometry>
                <mesh filename="package://moveo-0105_description/meshes/wrist1_1.stl" scale="0.001 0.001 0.001" />
            </geometry>
        </collision>
    </link>
    <link name="wrist2_1">
        <inertial>
            <origin rpy="0 0 0" xyz="1.7801637206019196e-05 0.00038597362461041245 0.003801159513988961" />
            <mass value="1.2441067270754815" />
            <inertia ixx="0.000701" ixy="-0.0" ixz="-1e-06" iyy="0.000835" iyz="-5e-06" izz="0.00059" />
        </inertial>
        <visual>
            <origin rpy="0 0 0" xyz="-0.0 1e-06 -0.676624" />
            <geometry>
                <mesh filename="package://moveo-0105_description/meshes/wrist2_1.stl" scale="0.001 0.001 0.001" />
            </geometry>
            <material name="opaque246246243" />
        </visual>
        <collision>
            <origin rpy="0 0 0" xyz="-0.0 1e-06 -0.676624" />
            <geometry>
                <mesh filename="package://moveo-0105_description/meshes/wrist2_1.stl" scale="0.001 0.001 0.001" />
            </geometry>
        </collision>
    </link>
    <link name="gripper_base_1">
        <inertial>
            <origin rpy="0 0 0" xyz="0.013185520099364393 -0.001654878047983701 0.02284446108224336" />
            <mass value="0.6076600420750945" />
            <inertia ixx="0.00023" ixy="2.1e-05" ixz="-4.8e-05" iyy="0.000321" iyz="6e-06" izz="0.000334" />
        </inertial>
        <visual>
            <origin rpy="0 0 0" xyz="-0.000192 1e-06 -0.717623" />
            <geometry>
                <mesh filename="package://moveo-0105_description/meshes/gripper_base_1.stl" scale="0.001 0.001 0.001" />
            </geometry>
            <material name="opaque246246243" />
        </visual>
        <collision>
            <origin rpy="0 0 0" xyz="-0.000192 1e-06 -0.717623" />
            <geometry>
                <mesh filename="package://moveo-0105_description/meshes/gripper_base_1.stl" scale="0.001 0.001 0.001" />
            </geometry>
        </collision>
    </link>
    <joint name="Revolute 1" type="continuous">
        <origin rpy="0 0 0" xyz="0.0 0.0 0.081" />
        <parent link="base_link" />
        <child link="base_1" />
        <axis xyz="0.0 0.0 1.0" />
    </joint>
    <joint name="Revolute 2" type="continuous">
        <origin rpy="0 0 0" xyz="0.0 0.0 0.142" />
        <parent link="base_1" />
        <child link="shoulder_1" />
        <axis xyz="0.0 1.0 0.0" />
    </joint>
    <joint name="Revolute 4" type="continuous">
        <origin rpy="0 0 0" xyz="-0.0 -0.0 0.221124" />
        <parent link="shoulder_1" />
        <child link="elbow_1" />
        <axis xyz="-0.0 -1.0 0.0" />
    </joint>
    <joint name="Revolute 5" type="continuous">
        <origin rpy="0 0 0" xyz="0.0 -1e-06 0.1335" />
        <parent link="elbow_1" />
        <child link="wrist1_1" />
        <axis xyz="0.0 -0.0 -1.0" />
    </joint>
    <joint name="Revolute 6" type="continuous">
        <origin rpy="0 0 0" xyz="0.0 0.0 0.099" />
        <parent link="wrist1_1" />
        <child link="wrist2_1" />
        <axis xyz="-0.0 -1.0 0.0" />
    </joint>
    <joint name="Rigid 7" type="fixed">
        <origin rpy="0 0 0" xyz="0.000192 0.0 0.040999" />
        <parent link="wrist2_1" />
        <child link="gripper_base_1" />
    </joint>
</robot>

