<?xml version="1.0" ?>
<robot name="moveo-0105" xmlns:xacro="http://www.ros.org/wiki/xacro">

<xacro:include filename="$(find moveo-0105_description)/urdf/materials.xacro" />
<xacro:include filename="$(find moveo-0105_description)/urdf/moveo-0105.trans" />
<xacro:include filename="$(find moveo-0105_description)/urdf/moveo-0105.gazebo" />
<link name="base_link">
  <inertial>
    <origin xyz="-0.04353915195820223 1.1802868267869896e-05 0.02880043175983316" rpy="0 0 0"/>
    <mass value="14.165231902745852"/>
    <inertia ixx="0.043748" iyy="0.104813" izz="0.129844" ixy="1.1e-05" iyz="3e-06" ixz="-0.004239"/>
  </inertial>
  <visual>
    <origin xyz="0 0 0" rpy="0 0 0"/>
    <geometry>
      <mesh filename="package://moveo-0105_description/meshes/base_link.stl" scale="0.001 0.001 0.001"/>
    </geometry>
    <material name="opaque246246243"/>
  </visual>
  <collision>
    <origin xyz="0 0 0" rpy="0 0 0"/>
    <geometry>
      <mesh filename="package://moveo-0105_description/meshes/base_link.stl" scale="0.001 0.001 0.001"/>
    </geometry>
  </collision>
</link>

<link name="base_1">
  <inertial>
    <origin xyz="-3.7076303009149166e-05 0.014076271479158351 0.07047518337511922" rpy="0 0 0"/>
    <mass value="13.837333116090063"/>
    <inertia ixx="0.087139" iyy="0.056559" izz="0.05967" ixy="2.4e-05" iyz="0.005688" ixz="-1.5e-05"/>
  </inertial>
  <visual>
    <origin xyz="-0.0 -0.0 -0.081" rpy="0 0 0"/>
    <geometry>
      <mesh filename="package://moveo-0105_description/meshes/base_1.stl" scale="0.001 0.001 0.001"/>
    </geometry>
    <material name="opaque246246243"/>
  </visual>
  <collision>
    <origin xyz="-0.0 -0.0 -0.081" rpy="0 0 0"/>
    <geometry>
      <mesh filename="package://moveo-0105_description/meshes/base_1.stl" scale="0.001 0.001 0.001"/>
    </geometry>
  </collision>
</link>

<link name="shoulder_1">
  <inertial>
    <origin xyz="-1.864413666055061e-05 -0.0016829757344041373 0.079876392750896" rpy="0 0 0"/>
    <mass value="15.137044414850111"/>
    <inertia ixx="0.134132" iyy="0.127723" izz="0.028256" ixy="2.6e-05" iyz="0.000957" ixz="0.000117"/>
  </inertial>
  <visual>
    <origin xyz="-0.0 -0.0 -0.223" rpy="0 0 0"/>
    <geometry>
      <mesh filename="package://moveo-0105_description/meshes/shoulder_1.stl" scale="0.001 0.001 0.001"/>
    </geometry>
    <material name="opaque246246243"/>
  </visual>
  <collision>
    <origin xyz="-0.0 -0.0 -0.223" rpy="0 0 0"/>
    <geometry>
      <mesh filename="package://moveo-0105_description/meshes/shoulder_1.stl" scale="0.001 0.001 0.001"/>
    </geometry>
  </collision>
</link>

<link name="elbow_1">
  <inertial>
    <origin xyz="1.0586701587362072e-07 2.396546815964754e-07 0.04247458254047237" rpy="0 0 0"/>
    <mass value="0.7464260010795348"/>
    <inertia ixx="0.002345" iyy="0.002358" izz="0.000749" ixy="0.0" iyz="0.0" ixz="0.0"/>
  </inertial>
  <visual>
    <origin xyz="0.0 0.0 -0.444124" rpy="0 0 0"/>
    <geometry>
      <mesh filename="package://moveo-0105_description/meshes/elbow_1.stl" scale="0.001 0.001 0.001"/>
    </geometry>
    <material name="abs_white"/>
  </visual>
  <collision>
    <origin xyz="0.0 0.0 -0.444124" rpy="0 0 0"/>
    <geometry>
      <mesh filename="package://moveo-0105_description/meshes/elbow_1.stl" scale="0.001 0.001 0.001"/>
    </geometry>
  </collision>
</link>

<link name="wrist1_1">
  <inertial>
    <origin xyz="0.00015462808202342042 0.0025523371121374885 0.055229105478112106" rpy="0 0 0"/>
    <mass value="2.633340777705091"/>
    <inertia ixx="0.005484" iyy="0.004502" izz="0.002738" ixy="-8e-06" iyz="8.8e-05" ixz="3.8e-05"/>
  </inertial>
  <visual>
    <origin xyz="0.0 1e-06 -0.577624" rpy="0 0 0"/>
    <geometry>
      <mesh filename="package://moveo-0105_description/meshes/wrist1_1.stl" scale="0.001 0.001 0.001"/>
    </geometry>
    <material name="opaque246246243"/>
  </visual>
  <collision>
    <origin xyz="0.0 1e-06 -0.577624" rpy="0 0 0"/>
    <geometry>
      <mesh filename="package://moveo-0105_description/meshes/wrist1_1.stl" scale="0.001 0.001 0.001"/>
    </geometry>
  </collision>
</link>

<link name="wrist2_1">
  <inertial>
    <origin xyz="1.7801637206019196e-05 0.00038597362461041245 0.003801159513988961" rpy="0 0 0"/>
    <mass value="1.2441067270754815"/>
    <inertia ixx="0.000701" iyy="0.000835" izz="0.00059" ixy="-0.0" iyz="-5e-06" ixz="-1e-06"/>
  </inertial>
  <visual>
    <origin xyz="-0.0 1e-06 -0.676624" rpy="0 0 0"/>
    <geometry>
      <mesh filename="package://moveo-0105_description/meshes/wrist2_1.stl" scale="0.001 0.001 0.001"/>
    </geometry>
    <material name="opaque246246243"/>
  </visual>
  <collision>
    <origin xyz="-0.0 1e-06 -0.676624" rpy="0 0 0"/>
    <geometry>
      <mesh filename="package://moveo-0105_description/meshes/wrist2_1.stl" scale="0.001 0.001 0.001"/>
    </geometry>
  </collision>
</link>

<link name="gripper_base_1">
  <inertial>
    <origin xyz="0.013185520099364393 -0.001654878047983701 0.02284446108224336" rpy="0 0 0"/>
    <mass value="0.6076600420750945"/>
    <inertia ixx="0.00023" iyy="0.000321" izz="0.000334" ixy="2.1e-05" iyz="6e-06" ixz="-4.8e-05"/>
  </inertial>
  <visual>
    <origin xyz="-0.000192 1e-06 -0.717623" rpy="0 0 0"/>
    <geometry>
      <mesh filename="package://moveo-0105_description/meshes/gripper_base_1.stl" scale="0.001 0.001 0.001"/>
    </geometry>
    <material name="opaque246246243"/>
  </visual>
  <collision>
    <origin xyz="-0.000192 1e-06 -0.717623" rpy="0 0 0"/>
    <geometry>
      <mesh filename="package://moveo-0105_description/meshes/gripper_base_1.stl" scale="0.001 0.001 0.001"/>
    </geometry>
  </collision>
</link>

<joint name="Revolute 1" type="continuous">
  <origin xyz="0.0 0.0 0.081" rpy="0 0 0"/>
  <parent link="base_link"/>
  <child link="base_1"/>
  <axis xyz="0.0 0.0 1.0"/>
</joint>

<joint name="Revolute 2" type="continuous">
  <origin xyz="0.0 0.0 0.142" rpy="0 0 0"/>
  <parent link="base_1"/>
  <child link="shoulder_1"/>
  <axis xyz="0.0 1.0 0.0"/>
</joint>

<joint name="Revolute 4" type="continuous">
  <origin xyz="-0.0 -0.0 0.221124" rpy="0 0 0"/>
  <parent link="shoulder_1"/>
  <child link="elbow_1"/>
  <axis xyz="-0.0 -1.0 0.0"/>
</joint>

<joint name="Revolute 5" type="continuous">
  <origin xyz="0.0 -1e-06 0.1335" rpy="0 0 0"/>
  <parent link="elbow_1"/>
  <child link="wrist1_1"/>
  <axis xyz="0.0 -0.0 -1.0"/>
</joint>

<joint name="Revolute 6" type="continuous">
  <origin xyz="0.0 0.0 0.099" rpy="0 0 0"/>
  <parent link="wrist1_1"/>
  <child link="wrist2_1"/>
  <axis xyz="-0.0 -1.0 0.0"/>
</joint>

<joint name="Rigid 7" type="fixed">
  <origin xyz="0.000192 0.0 0.040999" rpy="0 0 0"/>
  <parent link="wrist2_1"/>
  <child link="gripper_base_1"/>
</joint>

</robot>
