<?xml version="1.0" ?>
<!-- =================================================================================== -->
<!-- |    This document was autogenerated by xacro from /home/navneeth/catkin_ws/src/moveo_ros_cust_description/urdf/moveo_ros_cust.xacro | -->
<!-- |    EDITING THIS FILE BY HAND IS NOT RECOMMENDED                                 | -->
<!-- =================================================================================== -->
<robot name="moveo_ros_cust">
    <material name="silver_default">
        <color rgba="0.700 0.700 0.700 1.000" />
    </material>
    <material name="abs_white">
        <color rgba="0.9647058823529412 0.9647058823529412 0.9529411764705882 1.0" />
    </material>
    <material name="opaque198193188">
        <color rgba="0.7764705882352941 0.7568627450980392 0.7372549019607844 1.0" />
    </material>
    <material name="opaque102183255">
        <color rgba="0.4 0.7176470588235294 1.0 1.0" />
    </material>
    <material name="opaque15165255">
        <color rgba="0.058823529411764705 0.6470588235294118 1.0 1.0" />
    </material>
    <transmission name="j1_tran">
        <type>transmission_interface/SimpleTransmission</type>
        <joint name="j1">
            <hardwareInterface>hardware_interface/EffortJointInterface</hardwareInterface>
        </joint>
        <actuator name="j1_actr">
            <hardwareInterface>hardware_interface/EffortJointInterface</hardwareInterface>
            <mechanicalReduction>1</mechanicalReduction>
        </actuator>
    </transmission>
    <transmission name="j2_tran">
        <type>transmission_interface/SimpleTransmission</type>
        <joint name="j2">
            <hardwareInterface>hardware_interface/EffortJointInterface</hardwareInterface>
        </joint>
        <actuator name="j2_actr">
            <hardwareInterface>hardware_interface/EffortJointInterface</hardwareInterface>
            <mechanicalReduction>1</mechanicalReduction>
        </actuator>
    </transmission>
    <transmission name="j3_tran">
        <type>transmission_interface/SimpleTransmission</type>
        <joint name="j3">
            <hardwareInterface>hardware_interface/EffortJointInterface</hardwareInterface>
        </joint>
        <actuator name="j3_actr">
            <hardwareInterface>hardware_interface/EffortJointInterface</hardwareInterface>
            <mechanicalReduction>1</mechanicalReduction>
        </actuator>
    </transmission>
    <transmission name="j4_tran">
        <type>transmission_interface/SimpleTransmission</type>
        <joint name="j4">
            <hardwareInterface>hardware_interface/EffortJointInterface</hardwareInterface>
        </joint>
        <actuator name="j4_actr">
            <hardwareInterface>hardware_interface/EffortJointInterface</hardwareInterface>
            <mechanicalReduction>1</mechanicalReduction>
        </actuator>
    </transmission>
    <transmission name="j5_tran">
        <type>transmission_interface/SimpleTransmission</type>
        <joint name="j5">
            <hardwareInterface>hardware_interface/EffortJointInterface</hardwareInterface>
        </joint>
        <actuator name="j5_actr">
            <hardwareInterface>hardware_interface/EffortJointInterface</hardwareInterface>
            <mechanicalReduction>1</mechanicalReduction>
        </actuator>
    </transmission>
    <gazebo>
        <plugin filename="libgazebo_ros_control.so" name="control" />
        <plugin name="gazebo_ros_control">
            <robotNamespace>/</robotNamespace>
        </plugin>
    </gazebo>
    <gazebo reference="base_link">
        <material>Gazebo/Silver</material>
        <mu1>0.2</mu1>
        <mu2>0.2</mu2>
        <selfCollide>true</selfCollide>
        <gravity>true</gravity>
    </gazebo>
    <gazebo reference="moveo_base_1_1">
        <material>Gazebo/Silver</material>
        <mu1>0.2</mu1>
        <mu2>0.2</mu2>
        <selfCollide>true</selfCollide>
    </gazebo>
    <gazebo reference="moveo_shoulder_1_1">
        <material>Gazebo/Silver</material>
        <mu1>0.2</mu1>
        <mu2>0.2</mu2>
        <selfCollide>true</selfCollide>
    </gazebo>
    <gazebo reference="moveo_elbow_1_1">
        <material>Gazebo/Silver</material>
        <mu1>0.2</mu1>
        <mu2>0.2</mu2>
        <selfCollide>true</selfCollide>
    </gazebo>
    <gazebo reference="moveo_wrist1_1_1">
        <material>Gazebo/Silver</material>
        <mu1>0.2</mu1>
        <mu2>0.2</mu2>
        <selfCollide>true</selfCollide>
    </gazebo>
    <gazebo reference="moveo_wrist2_1_1">
        <material>Gazebo/Silver</material>
        <mu1>0.2</mu1>
        <mu2>0.2</mu2>
        <selfCollide>true</selfCollide>
    </gazebo>
    <gazebo reference="gripper_base_1_1">
        <material>Gazebo/Silver</material>
        <mu1>0.2</mu1>
        <mu2>0.2</mu2>
        <selfCollide>true</selfCollide>
    </gazebo>
    <link name="base_link">
        <inertial>
            <origin rpy="0 0 0" xyz="-0.04353912682058957 1.1841545783966033e-05 0.028800427511151794" />
            <mass value="1.912757204314006" />
            <inertia ixx="0.005907" ixy="1e-06" ixz="-0.000572" iyy="0.014153" iyz="0.0" izz="0.017533" />
        </inertial>
        <visual>
            <origin rpy="0 0 0" xyz="0 0 0" />
            <geometry>
                <mesh filename="package://moveo_ros_cust_description/meshes/base_link.stl" scale="0.001 0.001 0.001" />
            </geometry>
            <material name="abs_white" />
        </visual>
        <collision>
            <origin rpy="0 0 0" xyz="0 0 0" />
            <geometry>
                <mesh filename="package://moveo_ros_cust_description/meshes/base_link.stl" scale="0.001 0.001 0.001" />
            </geometry>
        </collision>
    </link>
    <link name="moveo_base_1_1">
        <inertial>
            <origin rpy="0 0 0" xyz="3.7101256680002715e-05 -0.014073349273890751 0.06848966282661016" />
            <mass value="13.84026194492548" />
            <inertia ixx="0.087165" ixy="2.4e-05" ixz="1.5e-05" iyy="0.056574" iyz="-0.005691" izz="0.059683" />
        </inertial>
        <visual>
            <origin rpy="0 0 0" xyz="-0.0 -0.0 -0.081" />
            <geometry>
                <mesh filename="package://moveo_ros_cust_description/meshes/moveo_base_1_1.stl" scale="0.001 0.001 0.001" />
            </geometry>
            <material name="abs_white" />
        </visual>
        <collision>
            <origin rpy="0 0 0" xyz="-0.0 -0.0 -0.081" />
            <geometry>
                <mesh filename="package://moveo_ros_cust_description/meshes/moveo_base_1_1.stl" scale="0.001 0.001 0.001" />
            </geometry>
        </collision>
    </link>
    <link name="moveo_shoulder_1_1">
        <inertial>
            <origin rpy="0 0 0" xyz="-0.00011395316940733614 0.04582773320713201 0.07990096172786262" />
            <mass value="15.143117648509138" />
            <inertia ixx="0.134198" ixy="2.8e-05" ixz="4e-06" iyy="0.127781" iyz="0.000965" izz="0.028267" />
        </inertial>
        <visual>
            <origin rpy="0 0 0" xyz="0.0 0.04825 -0.221" />
            <geometry>
                <mesh filename="package://moveo_ros_cust_description/meshes/moveo_shoulder_1_1.stl" scale="0.001 0.001 0.001" />
            </geometry>
            <material name="abs_white" />
        </visual>
        <collision>
            <origin rpy="0 0 0" xyz="0.0 0.04825 -0.221" />
            <geometry>
                <mesh filename="package://moveo_ros_cust_description/meshes/moveo_shoulder_1_1.stl" scale="0.001 0.001 0.001" />
            </geometry>
        </collision>
    </link>
    <link name="moveo_elbow_1_1">
        <inertial>
            <origin rpy="0 0 0" xyz="7.617983268293992e-05 -0.039052945227758346 0.043052962375156156" />
            <mass value="6.107478523844337" />
            <inertia ixx="0.017909" ixy="1e-06" ixz="5e-06" iyy="0.018062" iyz="0.00024" izz="0.005736" />
        </inertial>
        <visual>
            <origin rpy="0 0 0" xyz="0.0 -0.03875 -0.442124" />
            <geometry>
                <mesh filename="package://moveo_ros_cust_description/meshes/moveo_elbow_1_1.stl" scale="0.001 0.001 0.001" />
            </geometry>
            <material name="opaque198193188" />
        </visual>
        <collision>
            <origin rpy="0 0 0" xyz="0.0 -0.03875 -0.442124" />
            <geometry>
                <mesh filename="package://moveo_ros_cust_description/meshes/moveo_elbow_1_1.stl" scale="0.001 0.001 0.001" />
            </geometry>
        </collision>
    </link>
    <link name="moveo_wrist1_1_1">
        <inertial>
            <origin rpy="0 0 0" xyz="0.00015436797139384216 0.0025482476921564277 0.05125196284811462" />
            <mass value="0.35615599080577137" />
            <inertia ixx="0.000742" ixy="-1e-06" ixz="5e-06" iyy="0.000609" iyz="1.2e-05" izz="0.00037" />
        </inertial>
        <visual>
            <origin rpy="0 0 0" xyz="-0.0 0.001002 -0.575624" />
            <geometry>
                <mesh filename="package://moveo_ros_cust_description/meshes/moveo_wrist1_1_1.stl" scale="0.001 0.001 0.001" />
            </geometry>
            <material name="abs_white" />
        </visual>
        <collision>
            <origin rpy="0 0 0" xyz="-0.0 0.001002 -0.575624" />
            <geometry>
                <mesh filename="package://moveo_ros_cust_description/meshes/moveo_wrist1_1_1.stl" scale="0.001 0.001 0.001" />
            </geometry>
        </collision>
    </link>
    <link name="moveo_wrist2_1_1">
        <inertial>
            <origin rpy="0 0 0" xyz="7.764894814559006e-10 0.02438597363850794 0.0038012012605138645" />
            <mass value="0.16799402953278994" />
            <inertia ixx="9.5e-05" ixy="-0.0" ixz="0.0" iyy="0.000113" iyz="-1e-06" izz="8e-05" />
        </inertial>
        <visual>
            <origin rpy="0 0 0" xyz="-0.0 0.026002 -0.670624" />
            <geometry>
                <mesh filename="package://moveo_ros_cust_description/meshes/moveo_wrist2_1_1.stl" scale="0.001 0.001 0.001" />
            </geometry>
            <material name="abs_white" />
        </visual>
        <collision>
            <origin rpy="0 0 0" xyz="-0.0 0.026002 -0.670624" />
            <geometry>
                <mesh filename="package://moveo_ros_cust_description/meshes/moveo_wrist2_1_1.stl" scale="0.001 0.001 0.001" />
            </geometry>
        </collision>
    </link>
    <link name="gripper_base_1_1">
        <inertial>
            <origin rpy="0 0 0" xyz="-0.030138148928027426 0.013915645537354122 0.034103445881066397" />
            <mass value="0.07088399017612114" />
            <inertia ixx="2.4e-05" ixy="2e-06" ixz="3e-06" iyy="3.4e-05" iyz="-0.0" izz="3.9e-05" />
        </inertial>
        <visual>
            <origin rpy="0 0 0" xyz="-0.015 0.014002 -0.711624" />
            <geometry>
                <mesh filename="package://moveo_ros_cust_description/meshes/gripper_base_1_1.stl" scale="0.001 0.001 0.001" />
            </geometry>
            <material name="abs_white" />
        </visual>
        <collision>
            <origin rpy="0 0 0" xyz="-0.015 0.014002 -0.711624" />
            <geometry>
                <mesh filename="package://moveo_ros_cust_description/meshes/gripper_base_1_1.stl" scale="0.001 0.001 0.001" />
            </geometry>
        </collision>
    </link>
    <joint name="j1" type="continuous">
        <origin rpy="0 0 0" xyz="0.0 0.0 0.081" />
        <parent link="base_link" />
        <child link="moveo_base_1_1" />
        <axis xyz="0.0 0.0 1.0" />
    </joint>
    <joint name="j2" type="continuous">
        <origin rpy="0 0 0" xyz="-0.0 -0.04825 0.14" />
        <parent link="moveo_base_1_1" />
        <child link="moveo_shoulder_1_1" />
        <axis xyz="0.0 1.0 -0.0" />
    </joint>
    <joint name="j3" type="continuous">
        <origin rpy="0 0 0" xyz="0.0 0.087 0.221124" />
        <parent link="moveo_shoulder_1_1" />
        <child link="moveo_elbow_1_1" />
        <axis xyz="0.0 1.0 -0.0" />
    </joint>
    <joint name="j4" type="continuous">
        <origin rpy="0 0 0" xyz="0.0 -0.039752 0.1335" />
        <parent link="moveo_elbow_1_1" />
        <child link="moveo_wrist1_1_1" />
        <axis xyz="0.0 -0.0 -1.0" />
    </joint>
    <joint name="j5" type="continuous">
        <origin rpy="0 0 0" xyz="0.0 -0.025 0.095" />
        <parent link="moveo_wrist1_1_1" />
        <child link="moveo_wrist2_1_1" />
        <axis xyz="0.0 1.0 -0.0" />
    </joint>
    <joint name="Rigid 24" type="fixed">
        <origin rpy="0 0 0" xyz="0.015 0.012 0.041" />
        <parent link="moveo_wrist2_1_1" />
        <child link="gripper_base_1_1" />
    </joint>
</robot>

